{"trial_id": "056", "hyperparameters": {"space": [{"class_name": "Choice", "config": {"name": "filters_block1", "default": 32, "conditions": [], "values": [32, 64], "ordered": true}}, {"class_name": "Choice", "config": {"name": "filters_block2", "default": 64, "conditions": [], "values": [64, 128], "ordered": true}}, {"class_name": "Int", "config": {"name": "dense_units", "default": null, "conditions": [], "min_value": 256, "max_value": 512, "step": 128, "sampling": "linear"}}, {"class_name": "Choice", "config": {"name": "learning_rate", "default": 0.01, "conditions": [], "values": [0.01, 0.001, 0.0001], "ordered": true}}, {"class_name": "Float", "config": {"name": "dropout_dense", "default": 0.3, "conditions": [], "min_value": 0.3, "max_value": 0.6, "step": 0.1, "sampling": "linear"}}, {"class_name": "Choice", "config": {"name": "optimizer", "default": "adam", "conditions": [], "values": ["adam", "rmsprop", "sgd", "adagrad"], "ordered": false}}], "values": {"filters_block1": 32, "filters_block2": 64, "dense_units": 384, "learning_rate": 0.001, "dropout_dense": 0.5, "optimizer": "adam"}}, "metrics": {"metrics": {}}, "score": null, "best_step": 0, "status": "FAILED", "message": "Traceback (most recent call last):\n  File \"c:\\Users\\geo_s\\Documents\\MICAI 2025\\MedMNIST\\.venv\\Lib\\site-packages\\keras_tuner\\src\\engine\\base_tuner.py\", line 274, in _try_run_and_update_trial\n    self._run_and_update_trial(trial, *fit_args, **fit_kwargs)\n    ~~~~~~~~~~~~~~~~~~~~~~~~~~^^^^^^^^^^^^^^^^^^^^^^^^^^^^^^^^\n  File \"c:\\Users\\geo_s\\Documents\\MICAI 2025\\MedMNIST\\.venv\\Lib\\site-packages\\keras_tuner\\src\\engine\\base_tuner.py\", line 239, in _run_and_update_trial\n    results = self.run_trial(trial, *fit_args, **fit_kwargs)\n  File \"c:\\Users\\geo_s\\Documents\\MICAI 2025\\MedMNIST\\.venv\\Lib\\site-packages\\keras_tuner\\src\\engine\\tuner.py\", line 314, in run_trial\n    obj_value = self._build_and_fit_model(trial, *args, **copied_kwargs)\n  File \"c:\\Users\\geo_s\\Documents\\MICAI 2025\\MedMNIST\\.venv\\Lib\\site-packages\\keras_tuner\\src\\engine\\tuner.py\", line 233, in _build_and_fit_model\n    results = self.hypermodel.fit(hp, model, *args, **kwargs)\n  File \"c:\\Users\\geo_s\\Documents\\MICAI 2025\\MedMNIST\\.venv\\Lib\\site-packages\\keras_tuner\\src\\engine\\hypermodel.py\", line 149, in fit\n    return model.fit(*args, **kwargs)\n           ~~~~~~~~~^^^^^^^^^^^^^^^^^\n  File \"c:\\Users\\geo_s\\Documents\\MICAI 2025\\MedMNIST\\.venv\\Lib\\site-packages\\keras\\src\\utils\\traceback_utils.py\", line 122, in error_handler\n    raise e.with_traceback(filtered_tb) from None\n  File \"c:\\Users\\geo_s\\Documents\\MICAI 2025\\MedMNIST\\.venv\\Lib\\site-packages\\keras_tuner\\src\\engine\\tuner_utils.py\", line 76, in on_epoch_end\n    self._save_model()\n    ~~~~~~~~~~~~~~~~^^\n  File \"c:\\Users\\geo_s\\Documents\\MICAI 2025\\MedMNIST\\.venv\\Lib\\site-packages\\keras_tuner\\src\\engine\\tuner_utils.py\", line 86, in _save_model\n    self.model.save_weights(write_filepath)\n    ~~~~~~~~~~~~~~~~~~~~~~~^^^^^^^^^^^^^^^^\n  File \"c:\\Users\\geo_s\\Documents\\MICAI 2025\\MedMNIST\\.venv\\Lib\\site-packages\\h5py\\_hl\\files.py\", line 564, in __init__\n    fid = make_fid(name, mode, userblock_size, fapl, fcpl, swmr=swmr)\n  File \"c:\\Users\\geo_s\\Documents\\MICAI 2025\\MedMNIST\\.venv\\Lib\\site-packages\\h5py\\_hl\\files.py\", line 244, in make_fid\n    fid = h5f.create(name, h5f.ACC_TRUNC, fapl=fapl, fcpl=fcpl)\n  File \"h5py/_objects.pyx\", line 56, in h5py._objects.with_phil.wrapper\n  File \"h5py/_objects.pyx\", line 57, in h5py._objects.with_phil.wrapper\n  File \"h5py/h5f.pyx\", line 122, in h5py.h5f.create\nOSError: [Errno 22] Unable to synchronously create file (unable to open file: name = 'keras_tuner_dir\\breast_cancer_optimization\\trial_056\\checkpoint.weights.h5', errno = 22, error message = 'Invalid argument', flags = 13, o_flags = 302)\n"}